<?xml version="1.0" ?>
<!-- =================================================================================== -->
<!-- |    This document was autogenerated by xacro from smallrobot.urdf.xacro          | -->
<!-- |    EDITING THIS FILE BY HAND IS NOT RECOMMENDED                                 | -->
<!-- =================================================================================== -->
<!-- =================================================================================== -->
<!-- |    This document was autogenerated by xacro from
/home/roach/ros2_ws/src/smallrobot_description/urdf/smallrobot_description.xacro | -->
<!-- |    EDITING THIS FILE BY HAND IS NOT RECOMMENDED                                 | -->
<!-- =================================================================================== -->
<robot name="smallrobot">
  <!-- smallrobot_hw is the hw component name -->
  <ros2_control name="smallrobot_hw" type="system">
    <hardware>
      <plugin>gz_ros2_control/GazeboSimSystem</plugin>
    </hardware>
    <joint name="joint1">
      <command_interface name="position">
        <param name="min">-1.98</param>
        <param name="max">1.98</param>
      </command_interface>
      <state_interface name="position"/>
      <state_interface name="velocity"/>
    </joint>
    <joint name="joint2">
      <command_interface name="position">
        <param name="min">-1.41</param>
        <param name="max">1.34</param>
      </command_interface>
      <state_interface name="position"/>
      <state_interface name="velocity"/>
    </joint>
    <joint name="joint3">
      <command_interface name="position">
        <param name="min">-3.14159</param>
        <param name="max">1.22</param>
      </command_interface>
      <state_interface name="position"/>
      <state_interface name="velocity"/>
    </joint>
    <joint name="joint4">
      <command_interface name="position">
        <param name="min">-3.14159</param>
        <param name="max">3.14159</param>
      </command_interface>
      <state_interface name="position"/>
      <state_interface name="velocity"/>
    </joint>
    <joint name="joint5">
      <command_interface name="position">
        <param name="min">-2.42</param>
        <param name="max">2.42</param>
      </command_interface>
      <state_interface name="position"/>
      <state_interface name="velocity"/>
    </joint>
    <joint name="joint6">
      <command_interface name="position">
        <param name="min">-3.14159</param>
        <param name="max">3.14159</param>
      </command_interface>
      <state_interface name="position"/>
      <state_interface name="velocity"/>
    </joint>
    <joint name="gripper_left_joint">
      <command_interface name="position">
        <param name="min">-0.01</param>
        <param name="max">0.019</param>
      </command_interface>
      <state_interface name="position"/>
      <state_interface name="velocity"/>
    </joint>
    <!-- <joint name="gripper_right_joint">     
    </joint> -->
  </ros2_control>
  <link name="world"/>
  <!-- Fixed joint from world to base_link -->
  <joint name="world_to_base" type="fixed">
    <origin rpy="0 0 0" xyz="0 0 0"/>
    <parent link="world"/>
    <child link="base_link"/>
  </joint>
  <link name="base_link">
    <inertial>
      <origin rpy="0 0 0" xyz="0.047 0.0121 0.125"/>
      <mass value="2.5"/>
      <inertia ixx="0.20750000000000002" ixy="0.001" ixz="0.002" iyy="0.20750000000000002" iyz="0.001" izz="0.0625"/>
    </inertial>
    <visual>
      <origin rpy="0 0 3.14159" xyz="0.047 0.0121 0.25"/>
      <geometry>
        <mesh filename="package://smallrobot_description/meshes/link1.STL"/>
        <!-- <box size="0.5 0.5 0.5"/> -->
      </geometry>
      <material name="orange">
        <color rgba="1.0 0.5 0.0 0.8"/>
      </material>
    </visual>
    <collision>
      <origin rpy="0 0 3.14159" xyz="0.047 0.0121 0.25"/>
      <geometry>
        <mesh filename="package://smallrobot_description/meshes/link1.STL"/>
      </geometry>
    </collision>
  </link>
  <joint name="joint1" type="revolute">
    <origin rpy="0 0 0" xyz="0 0 0.043"/>
    <axis xyz="0 0 1"/>
    <limit acceleration="2.0" effort="10" lower="-2.0" upper="2.0" velocity="4.8"/>
    <parent link="base_link"/>
    <child link="link1"/>
  </joint>
  <link name="link1">
    <inertial>
      <origin rpy="0 0 0" xyz="0.047 0.012 0.208"/>
      <mass value="1.2"/>
      <inertia ixx="0.054" ixy="0.001" ixz="0.001" iyy="0.054" iyz="0.001" izz="0.018"/>
    </inertial>
    <visual>
      <origin rpy="0 0 3.14159" xyz="0.047 0.012 0.208"/>
      <geometry>
        <mesh filename="package://smallrobot_description/meshes/link2.STL"/>
      </geometry>
      <material name="orange">
        <color rgba="1.0 0.5 0.0 0.8"/>
      </material>
    </visual>
    <collision>
      <origin rpy="0 0 3.14159" xyz="0.047 0.012 0.208"/>
      <geometry>
        <mesh filename="package://smallrobot_description/meshes/link2.STL"/>
      </geometry>
    </collision>
  </link>
  <joint name="joint2" type="revolute">
    <origin rpy="0 0 0" xyz="0.047 -0.0485 0.098"/>
    <axis xyz="0 1 0"/>
    <limit lower="-1.5707963" upper="3.1415926" effort="100" velocity="0.4" />
    <limit acceleration="2.0" effort="10" lower="-1.570795" upper="3.14159" velocity="4.8"/>
    <parent link="link1"/>
    <child link="link2"/>
  </joint>
  <link name="link2">
    <inertial>
      <origin rpy="0 0 0" xyz="0 0.04 0.055"/>
      <mass value="0.8"/>
      <inertia ixx="0.009600000000000001" ixy="0" ixz="0" iyy="0.020000000000000004" iyz="0.002" izz="0.016"/>
    </inertial>
    <visual>
      <origin rpy="1.570795 0 3.14159" xyz="0 0 0"/>
      <geometry>
        <mesh filename="package://smallrobot_description/meshes/link3.STL"/>
      </geometry>
      <material name="orange">
        <color rgba="1.0 0.5 0.0 0.8"/>
      </material>
    </visual>
    <collision>
      <origin rpy="1.570795 0 3.14159" xyz="0 0 0"/>
      <geometry>
        <mesh filename="package://smallrobot_description/meshes/link3.STL"/>
      </geometry>
    </collision>
  </link>
  <joint name="joint3" type="revolute">
    <origin rpy="0 0 0" xyz="0 0.08 0.111"/>
    <axis xyz="0 1 0"/>
    <limit acceleration="2.0" effort="10" lower="-3.14159" upper="1.570795" velocity="4.8"/>
    <parent link="link2"/>
    <child link="link3"/>
  </joint>
  <link name="link3">
    <inertial>
      <origin rpy="0 0 0" xyz="-0.013 -0.015 0.013"/>
      <mass value="0.3"/>
      <inertia ixx="0.0009" ixy="0" ixz="0" iyy="0.0024" iyz="0" izz="0.0024"/>
    </inertial>
    <visual>
      <origin rpy="0 0 3.14159" xyz="0.08 -0.0286 0.01"/>
      <geometry>
        <mesh filename="package://smallrobot_description/meshes/link4.STL"/>
      </geometry>
      <material name="orange">
        <color rgba="1.0 0.5 0.0 0.8"/>
      </material>
    </visual>
    <collision>
      <origin rpy="0 0 3.14159" xyz="0.08 -0.0286 0.01"/>
      <geometry>
        <mesh filename="package://smallrobot_description/meshes/link4.STL"/>
      </geometry>
    </collision>
  </link>
  <joint name="joint4" type="revolute">
    <origin rpy="0 1.570795 0" xyz="-0.026 -0.0316 0.0258"/>
    <axis xyz="0 0 1"/>
    <limit acceleration="2.0" effort="10" lower="-1.570795" upper="1.570795" velocity="4.8"/>
    <parent link="link3"/>
    <child link="link4"/>
  </joint>
  <link name="link4">
    <inertial>
      <origin rpy="0 0 0" xyz="0.008 0.001 0.072"/>
      <mass value="0.25"/>
      <inertia ixx="0.0045" ixy="0" ixz="0" iyy="0.0045" iyz="0" izz="0.0005"/>
    </inertial>
    <visual>
      <origin rpy="0 1.570795 1.570795" xyz="0.016 0.003 0.106"/>
      <geometry>
        <mesh filename="package://smallrobot_description/meshes/link5.STL">
        </mesh>
      </geometry>
      <material name="orange">
        <color rgba="1.0 0.5 0.0 0.8"/>
      </material>
    </visual>
    <collision>
      <origin rpy="0 1.570795 1.570795" xyz="0.016 0.003 0.106"/>
      <geometry>
        <mesh filename="package://smallrobot_description/meshes/link5.STL"/>
      </geometry>
    </collision>
  </link>
  <joint name="joint5" type="revolute">
    <origin rpy="0 -1.570795 0" xyz="0 0 0.144"/>
    <axis xyz="0 1 0"/>
    <limit acceleration="2.0" effort="10" lower="-3.14159" upper="3.14159" velocity="4.8"/>
    <parent link="link4"/>
    <child link="link5"/>
  </joint>
  <link name="link5">
    <inertial>
      <origin rpy="0 0 0" xyz="0.009 0 0"/>
      <mass value="0.15"/>
      <inertia ixx="0.00015" ixy="0" ixz="0" iyy="0.0003" iyz="0" izz="0.0003"/>
    </inertial>
    <visual>
      <origin rpy="3.14159 0 -1.570795" xyz="0.018 0 0"/>
      <geometry>
        <mesh filename="package://smallrobot_description/meshes/link6.STL"/>
      </geometry>
      <material name="orange">
        <color rgba="1.0 0.5 0.0 0.8"/>
      </material>
    </visual>
    <collision>
      <origin rpy="3.14159 0 -1.570795" xyz="0.018 0 0"/>
      <geometry>
        <mesh filename="package://smallrobot_description/meshes/link6.STL"/>
      </geometry>
    </collision>
  </link>
  <joint name="joint6" type="revolute">
    <origin rpy="0 0 0" xyz="0.0253 0 0"/>
    <axis xyz="1 0 0"/>
    <limit lower="-3.1415926" upper="3.1415926" effort="100" velocity="0.4" />
    <limit acceleration="2.0" effort="10" lower="-3.14159" upper="3.14159" velocity="4.8"/>
    <parent link="link5"/>
    <child link="link6"/>
  </joint>
  <link name="link6">
    <inertial>
      <origin rpy="0 0 0" xyz="-0.028 0.002 -0.008"/>
      <mass value="0.1"/>
      <inertia ixx="0.0001" ixy="0" ixz="0" iyy="0.00030000000000000003" iyz="0" izz="0.00030000000000000003"/>
    </inertial>
    <visual>
      <origin rpy="0 0 3.14159" xyz="-0.0555 0.003 -0.016"/>
      <geometry>
        <mesh filename="package://smallrobot_description/meshes/link7.STL"/>
      </geometry>
      <material name="orange">
        <color rgba="1.0 0.5 0.0 0.8"/>
      </material>
    </visual>
    <collision>
      <origin rpy="0 0 3.14159" xyz="-0.0555 0.003 -0.016"/>
      <geometry>
        <mesh filename="package://smallrobot_description/meshes/link7.STL"/>
      </geometry>
    </collision>
  </link>
  <link name="flange">
    <inertial>
      <origin xyz="0 0 0"/>
      <mass value="0.01"/>
      <inertia ixx="1.0e-06" ixy="0.0" ixz="0.0" iyy="1.0e-06" iyz="0.0" izz="1.0e-06"/>
    </inertial>
    <visual>
      <origin rpy="0 0 -1.570795" xyz="0 0 0"/>
      <geometry>
        <mesh filename="package://smallrobot_description/meshes//flange.stl" scale="0.001 0.001 0.001"/>
      </geometry>
      <material name="grey">
        <color rgba="0.2 0.2 0.2 1"/>
      </material>
    </visual>
    <collision>
      <origin rpy="0 0 0" xyz="0 0 0"/>
      <geometry>
        <box size="0.01 0.01 0.01"/>
      </geometry>
    </collision>
  </link>
  <joint name="link6_to_flange" type="fixed">
    <parent link="link6"/>
    <child link="flange"/>
    <origin rpy="0 0 0" xyz="0 0 0"/>
  </joint>
  <joint name="gripper_left_joint" type="prismatic">
    <parent link="flange"/>
    <child link="gripper_left_link"/>
    <origin rpy="0 0 0" xyz="0.0817 0.021 0.0"/>
    <axis xyz="0 1 0"/>
    <limit acceleration="2.0" effort="10" lower="-0.010" upper="0.019" velocity="04.8"/>
    <dynamics damping="0.1"/>
  </joint>
  <link name="gripper_left_link">
    <visual>
      <origin rpy="0 0 0" xyz="-0.062 0 0"/>
      <geometry>
        <mesh filename="package://smallrobot_description/meshes//gripper_left_palm.stl" scale="0.001 0.001 0.001"/>
      </geometry>
      <material name="grey">
        <color rgba="0.2 0.2 0.2 1"/>
      </material>
    </visual>
    <collision>
      <origin rpy="0 0 0" xyz="-0.062 0 0"/>
      <geometry>
        <mesh filename="package://smallrobot_description/meshes//gripper_left_palm.stl" scale="0.001 0.001 0.001"/>
      </geometry>
    </collision>
    <inertial>
      <origin xyz="0 0 0"/>
      <mass value="1.0e-03"/>
      <inertia ixx="1.0e-06" ixy="0.0" ixz="0.0" iyy="1.0e-06" iyz="0.0" izz="1.0e-06"/>
    </inertial>
  </link>
  <joint name="gripper_right_joint" type="prismatic">
    <parent link="flange"/>
    <child link="gripper_right_link"/>
    <origin rpy="0 0 0" xyz="0.0817 -0.021 0"/>
    <axis xyz="0 -1 0"/>
    <limit acceleration="2.0" effort="10" lower="-0.010" upper="0.019" velocity="04.8"/>
    <dynamics damping="0.7"/>
    <mimic joint="gripper_left_joint" multiplier="1"/>
  </joint>
  <link name="gripper_right_link">
    <visual>
      <origin rpy="0 0 0" xyz="-0.062 0 0"/>
      <geometry>
        <mesh filename="package://smallrobot_description/meshes//gripper_right_palm.stl" scale="0.001 0.001 0.001"/>
      </geometry>
      <material name="grey">
        <color rgba="0.2 0.2 0.2 1"/>
      </material>
    </visual>
    <collision>
      <origin rpy="0 0 0" xyz="-0.062 0 0"/>
      <geometry>
        <mesh filename="package://smallrobot_description/meshes//gripper_right_palm.stl" scale="0.001 0.001 0.001"/>
      </geometry>
    </collision>
    <inertial>
      <origin xyz="0 0 0"/>
      <mass value="1.0e-03"/>
      <inertia ixx="1.0e-06" ixy="0.0" ixz="0.0" iyy="1.0e-06" iyz="0.0" izz="1.0e-06"/>
    </inertial>
  </link>
  <joint name="end_effector_joint" type="fixed">
    <parent link="flange"/>
    <child link="end_effector_link"/>
    <origin rpy="0 0 0" xyz="0.05 0.0 0.0"/>
  </joint>
  <link name="end_effector_link">
  </link>
  <!-- <link name="ee_link" /> 
  <joint name="ee_fixed" type="fixed">
    <parent link="flange" />
    <child link="ee_link" />    
    <origin xyz="0 0 0.1" rpy="0 0 0" />
  </joint>  -->
</robot>
