<?xml version="1.0"?>
<!-- =================================================================================== -->
<!-- |    This document was autogenerated by xacro from /home/roach/ros2_ws/src/smallrobot_description/urdf/smallrobot_description.xacro | -->
<!-- |    EDITING THIS FILE BY HAND IS NOT RECOMMENDED                                 | -->
<!-- =================================================================================== -->
<robot xmlns:xacro="http://www.ros.org/wiki/xacro" name="smallrobot">
  <!-- PI & is_sim will be accessible from included xacro files -->
  <xacro:arg name='is_sim' default='true'/>
  <xacro:property name='PI' value='3.14159' />

  <!-- include gazebo parameters -->
  <xacro:include filename="$(find smallrobot_description)/urdf/smallrobot_gazebo.xacro" />

  <!-- include ros2_control plugins -->
  <xacro:include filename="$(find smallrobot_description)/urdf/smallrobot_ros2_control.xacro"/> 
  <!-- useful macros -->
  <xacro:include filename="$(find smallrobot_description)/urdf/smallrobot_macro.xacro"/> 

  <link name="world"/>
  <!-- Fixed joint from world to base_link -->
  <joint name="world_to_base" type="fixed">
    <origin xyz="0 0 0" rpy="0 0 0"/>
    <parent link="world"/>
    <child link="base_link"/>
  </joint>
  
  <link name="base_link">
    <xacro:default_inertial mass="1.0"/>
    <visual>
      <origin rpy="0 0 3.1415926" xyz="0.047 0.0121 0.25"/>
      <geometry>
        <mesh filename="package://smallrobot_description/meshes/link1.STL"/>
        <!-- <box size="0.5 0.5 0.5"/> -->
      </geometry>
      <xacro:default_material/>
    </visual>
    <collision>
      <origin rpy="0 0 3.1415926" xyz="0.047 0.0121 0.25"/>
      <geometry>
        <mesh filename="package://smallrobot_description/meshes/link1.STL"/>
      </geometry>
    </collision>   
  </link>
  
  <joint name="joint1" type="revolute">
    <origin rpy="0 0 0" xyz="0 0 0.043"/>
    <axis xyz="0 0 1"/>
    <limit effort="100" lower="-2.0" upper="2.0" velocity="1.57"/>
    <parent link="base_link"/>
    <child link="link1"/>
  </joint>

  <link name="link1">
    <xacro:default_inertial mass="0.5"/>    
    <visual>
      <origin rpy="0 0 3.1415926" xyz="0.047 0.012 0.208"/>
      <geometry>
        <mesh filename="package://smallrobot_description/meshes/link2.STL"/>
      </geometry>
      <xacro:default_material/>
    </visual>
    <collision>
      <origin rpy="0 0 3.1415926" xyz="0.047 0.012 0.208"/>
      <geometry>
        <mesh filename="package://smallrobot_description/meshes/link2.STL"/>
      </geometry>
    </collision>    
  </link>

  <joint name="joint2" type="revolute">
    <origin rpy="0 0 0" xyz="0.047 -0.0485 0.098"/>
    <axis xyz="0 1 0"/>
    <limit effort="100" lower="-1.5707963" upper="3.1415926" velocity="1.57"/>
    <parent link="link1"/>
    <child link="link2"/>
  </joint>

  <link name="link2">
    <xacro:default_inertial mass="0.3"/>
    <visual>
      <origin rpy="1.5707963 0 3.1415926" xyz="0 0 0"/>
      <geometry>
        <mesh filename="package://smallrobot_description/meshes/link3.STL"/>
      </geometry>
      <xacro:default_material/>
    </visual>
    <collision>
      <origin rpy="1.5707963 0 3.1415926" xyz="0 0 0"/>
      <geometry>
        <mesh filename="package://smallrobot_description/meshes/link3.STL"/>
      </geometry>
    </collision>
  </link>

  <joint name="joint3" type="revolute">
    <origin rpy="0 0 0" xyz="0 0.08 0.111"/>
    <axis xyz="0 1 0"/>
    <limit effort="100" lower="-3.1415926" upper="1.5707963" velocity="1.57"/>
    <parent link="link2"/>
    <child link="link3"/>
  </joint>

  <link name="link3">
    <xacro:default_inertial mass="0.1"/>
    <visual>
      <origin rpy="0 0 3.1415926" xyz="0.08 -0.0286 0.01"/>
      <geometry>
        <mesh filename="package://smallrobot_description/meshes/link4.STL"/>
      </geometry>
      <xacro:default_material/>
    </visual>
    <collision>
      <origin rpy="0 0 3.1415926" xyz="0.08 -0.0286 0.01"/>
      <geometry>
        <mesh filename="package://smallrobot_description/meshes/link4.STL"/>
      </geometry>
    </collision>
  </link>
  <joint name="joint4" type="revolute">
    <origin rpy="0 1.5707963 0" xyz="-0.026 -0.0316 0.0258"/>
    <axis xyz="0 0 1"/>
    <limit effort="100" lower="-1.5707963" upper="1.5707963" velocity="1.57"/>
    <parent link="link3"/>
    <child link="link4"/>
  </joint>

  <link name="link4">
    <xacro:default_inertial mass="0.1"/>
    <visual>
      <origin rpy="0 1.5707963 1.5707963" xyz="0.016 0.003 0.106"/>
      <geometry>
        <mesh filename="package://smallrobot_description/meshes/link5.STL">
        </mesh>
      </geometry>
      <xacro:default_material/>
    </visual>
    <collision>
      <origin rpy="0 1.5707963 1.5707963" xyz="0.016 0.003 0.106"/>
      <geometry>
        <mesh filename="package://smallrobot_description/meshes/link5.STL"/>
      </geometry>
    </collision>
  </link>

  <joint name="joint5" type="revolute">
    <origin rpy="0 -1.5707963 0" xyz="0 0 0.144"/>
    <axis xyz="0 1 0"/>
    <limit effort="100" lower="-3.1415926" upper="3.1415926" velocity="1.57"/>
    <parent link="link4"/>
    <child link="link5"/>
  </joint>

  <link name="link5">
    <xacro:default_inertial mass="0.02"/>
    <visual>
      <origin rpy="3.1415926 0 -1.5707963" xyz="0.018 0 0"/>
      <geometry>
        <mesh filename="package://smallrobot_description/meshes/link6.STL"/>
      </geometry>
      <xacro:default_material/>
    </visual>
    <collision>
      <origin rpy="3.1415926 0 -1.5707963" xyz="0.018 0 0"/>
      <geometry>
        <mesh filename="package://smallrobot_description/meshes/link6.STL"/>
      </geometry>
    </collision>
  </link>
  <joint name="joint6" type="revolute">
    <origin rpy="0 0 0" xyz="0.0253 0 0"/>
    <axis xyz="1 0 0"/>
    <limit effort="100" lower="-3.1415926" upper="3.1415926" velocity="1.57"/>
    <parent link="link5"/>
    <child link="link6"/>
  </joint>

  <link name="link6">
    <xacro:default_inertial mass="0.01"/>
    <visual>
      <origin rpy="0 0 3.1415926" xyz="-0.0555 0.003 -0.016"/>
      <geometry>
        <mesh filename="package://smallrobot_description/meshes/link7.STL"/>
      </geometry>
      <xacro:default_material/>
    </visual>
    <collision>
      <origin rpy="0 0 3.1415926" xyz="-0.0555 0.003 -0.016"/>
      <geometry>
        <mesh filename="package://smallrobot_description/meshes/link7.STL"/>
      </geometry>
    </collision>
  </link>
  <xacro:default_transmission number='1' reduction_ratio='4.8'/>
  <xacro:default_transmission number='2' reduction_ratio='4.0'/>
  <xacro:default_transmission number='3' reduction_ratio='5.0'/>
  <xacro:default_transmission number='4' reduction_ratio='2.8'/>
  <xacro:default_transmission number='5' reduction_ratio='2.1'/>
  <xacro:default_transmission number='6' reduction_ratio='1.0'/>   
 
</robot>
