<?xml version="1.0"?>
<!-- =================================================================================== -->
<!-- |    This document was autogenerated by xacro from
/home/roach/ros2_ws/src/smallrobot_description/urdf/smallrobot_description.xacro | -->
<!-- |    EDITING THIS FILE BY HAND IS NOT RECOMMENDED                                 | -->
<!-- =================================================================================== -->
<robot xmlns:xacro="http://www.ros.org/wiki/xacro" name="smallrobot">
  <!-- PI & is_sim will be accessible from included xacro files -->
  <xacro:arg name='is_sim' default='true' />
  <xacro:arg name="use_fake_hardware" default="false" />
  <xacro:arg name="fake_sensor_commands" default="false" />

  <xacro:property name='PI' value='3.14159' />
  <xacro:property
    name="meshes_file_direction"
    value="package://smallrobot_description/meshes/" />

  <!-- useful macros -->
  <xacro:include
    filename="$(find smallrobot_description)/urdf/smallrobot_macro.xacro" />

  <!-- include gazebo parameters -->
  <xacro:include
    filename="$(find smallrobot_description)/urdf/smallrobot_gazebo.xacro" />

  <!-- include ros2_control plugins -->
  <xacro:include
    filename="$(find smallrobot_description)/urdf/smallrobot_ros2_control.xacro" />

  <link name="world" />
  <!-- Fixed joint from world to base_link -->
  <joint
    name="world_to_base" type="fixed">
    <origin xyz="0 0 0" rpy="0 0 0" />
    <parent link="world" />
    <child link="base_link" />
  </joint>

  <link name="base_link">
    <xacro:default_inertial mass="1.0" />
    <visual>
      <origin rpy="0 0 ${PI}" xyz="0.047 0.0121 0.25" />
      <geometry>
        <mesh filename="package://smallrobot_description/meshes/link1.STL" />
        <!-- <box size="0.5 0.5 0.5"/> -->
      </geometry>
      <xacro:default_material />
    </visual>
    <collision>
      <origin rpy="0 0 ${PI}" xyz="0.047 0.0121 0.25" />
      <geometry>
        <mesh filename="package://smallrobot_description/meshes/link1.STL" />
      </geometry>
    </collision>
  </link>

  <joint
    name="joint1" type="revolute">
    <origin rpy="0 0 0" xyz="0 0 0.043" />
    <axis xyz="0 0 1" />
    <limit effort="100" lower="-2.0" upper="2.0" velocity="4.8" />
    <parent link="base_link" />
    <child link="link1" />
  </joint>

  <link name="link1">
    <xacro:default_inertial mass="0.5" />
    <visual>
      <origin rpy="0 0 ${PI}" xyz="0.047 0.012 0.208" />
      <geometry>
        <mesh filename="package://smallrobot_description/meshes/link2.STL" />
      </geometry>
      <xacro:default_material />
    </visual>
    <collision>
      <origin rpy="0 0 ${PI}" xyz="0.047 0.012 0.208" />
      <geometry>
        <mesh filename="package://smallrobot_description/meshes/link2.STL" />
      </geometry>
    </collision>
  </link>

  <joint
    name="joint2" type="revolute">
    <origin rpy="0 0 0" xyz="0.047 -0.0485 0.098" />
    <axis xyz="0 1 0" />
    <limit effort="100" lower="-${PI/2}" upper="${PI}" velocity="4.8" />
    <parent link="link1" />
    <child link="link2" />
  </joint>

  <link name="link2">
    <xacro:default_inertial mass="0.3" />
    <visual>
      <origin rpy="${PI/2} 0 ${PI}" xyz="0 0 0" />
      <geometry>
        <mesh filename="package://smallrobot_description/meshes/link3.STL" />
      </geometry>
      <xacro:default_material />
    </visual>
    <collision>
      <origin rpy="${PI/2} 0 ${PI}" xyz="0 0 0" />
      <geometry>
        <mesh filename="package://smallrobot_description/meshes/link3.STL" />
      </geometry>
    </collision>
  </link>

  <joint
    name="joint3" type="revolute">
    <origin rpy="0 0 0" xyz="0 0.08 0.111" />
    <axis xyz="0 1 0" />
    <limit effort="100" lower="-${PI}" upper="${PI/2}" velocity="4.8" />
    <parent link="link2" />
    <child link="link3" />
  </joint>

  <link name="link3">
    <xacro:default_inertial mass="0.1" />
    <visual>
      <origin rpy="0 0 ${PI}" xyz="0.08 -0.0286 0.01" />
      <geometry>
        <mesh filename="package://smallrobot_description/meshes/link4.STL" />
      </geometry>
      <xacro:default_material />
    </visual>
    <collision>
      <origin rpy="0 0 ${PI}" xyz="0.08 -0.0286 0.01" />
      <geometry>
        <mesh filename="package://smallrobot_description/meshes/link4.STL" />
      </geometry>
    </collision>
  </link>
  <joint
    name="joint4" type="revolute">
    <origin rpy="0 ${PI/2} 0" xyz="-0.026 -0.0316 0.0258" />
    <axis xyz="0 0 1" />
    <limit effort="100" lower="-${PI/2}" upper="${PI/2}" velocity="4.8" />
    <parent link="link3" />
    <child link="link4" />
  </joint>

  <link name="link4">
    <xacro:default_inertial mass="0.1" />
    <visual>
      <origin rpy="0 ${PI/2} ${PI/2}" xyz="0.016 0.003 0.106" />
      <geometry>
        <mesh filename="package://smallrobot_description/meshes/link5.STL">
        </mesh>
      </geometry>
      <xacro:default_material />
    </visual>
    <collision>
      <origin rpy="0 ${PI/2} ${PI/2}" xyz="0.016 0.003 0.106" />
      <geometry>
        <mesh filename="package://smallrobot_description/meshes/link5.STL" />
      </geometry>
    </collision>
  </link>

  <joint name="joint5" type="revolute">
    <origin rpy="0 -${PI/2} 0" xyz="0 0 0.144" />
    <axis xyz="0 1 0" />
    <limit effort="100" lower="-${PI}" upper="${PI}" velocity="4.8" />
    <parent link="link4" />
    <child link="link5" />
  </joint>

  <link name="link5">
    <xacro:default_inertial mass="0.02" />
    <visual>
      <origin rpy="${PI} 0 -${PI/2}" xyz="0.018 0 0" />
      <geometry>
        <mesh filename="package://smallrobot_description/meshes/link6.STL" />
      </geometry>
      <xacro:default_material />
    </visual>
    <collision>
      <origin rpy="${PI} 0 -${PI/2}" xyz="0.018 0 0" />
      <geometry>
        <mesh filename="package://smallrobot_description/meshes/link6.STL" />
      </geometry>
    </collision>
  </link>
  <joint name="joint6" type="revolute">
    <origin rpy="0 0 0" xyz="0.0253 0 0" />
    <axis xyz="1 0 0" />
    <limit effort="100" lower="-${PI}" upper="${PI}" velocity="4.8" />
    <parent link="link5" />
    <child link="link6" />
  </joint>

  <link name="link6">
    <xacro:default_inertial mass="0.01" />
    <visual>
      <origin rpy="0 0 ${PI}" xyz="-0.0555 0.003 -0.016" />
      <geometry>
        <mesh filename="package://smallrobot_description/meshes/link7.STL" />
      </geometry>
      <xacro:default_material />
    </visual>
    <collision>
      <origin rpy="0 0 ${PI}" xyz="-0.0555 0.003 -0.016" />
      <geometry>
        <mesh filename="package://smallrobot_description/meshes/link7.STL" />
      </geometry>
    </collision>
  </link>

  <link name="flange">
    <inertial>
      <origin xyz="0 0 0" />
      <mass value="0.01" />
      <inertia ixx="1.0e-06" ixy="0.0" ixz="0.0"
        iyy="1.0e-06" iyz="0.0"
        izz="1.0e-06" />
    </inertial>
    <visual>
      <origin xyz="0 0 0" rpy="0 0 -${PI/2}" />
      <geometry>
        <mesh filename="${meshes_file_direction}/flange.stl" scale="0.001 0.001 0.001" />
      </geometry>
      <material name="grey">
        <color rgba="0.2 0.2 0.2 1" />
      </material>
    </visual>
    <collision>
      <origin xyz="0 0 0" rpy="0 0 0" />
      <geometry>
        <box size="0.01 0.01 0.01" />
      </geometry>
    </collision>
  </link>

  <joint name="link6_to_flange" type="fixed">
    <parent link="link6" />
    <child link="flange" />
    <origin xyz="0 0 0" rpy="0 0 0" />
  </joint>

  <joint
    name="gripper_left_joint" type="prismatic">
    <parent link="flange" />
    <child link="gripper_left_link" />
    <origin xyz="0.0817 0.021 0.0" rpy="0 0 0" />
    <axis xyz="0 1 0" />
    <limit velocity="4.8" effort="1000" lower="-0.010" upper="0.019" />
    <dynamics damping="0.1" />
  </joint>

  <link name="gripper_left_link">
    <visual>
      <origin xyz="-0.062 0 0" rpy="0 0 0" />
      <geometry>
        <mesh filename="${meshes_file_direction}/gripper_left_palm.stl" scale="0.001 0.001 0.001" />
      </geometry>
      <material name="grey">
        <color rgba="0.2 0.2 0.2 1" />
      </material>
    </visual>

    <collision>
      <origin xyz="-0.062 0 0" rpy="0 0 0" />
      <geometry>
        <mesh filename="${meshes_file_direction}/gripper_left_palm.stl" scale="0.001 0.001 0.001" />
      </geometry>
    </collision>

    <inertial>
      <origin xyz="0 0 0" />
      <mass value="1.0e-03" />
      <inertia ixx="1.0e-06" ixy="0.0" ixz="0.0"
        iyy="1.0e-06" iyz="0.0"
        izz="1.0e-06" />
    </inertial>
  </link>

  <joint name="gripper_right_joint" type="prismatic">
    <parent link="flange" />
    <child link="gripper_right_link" />
    <origin xyz="0.0817 -0.021 0" rpy="0 0 0" />
    <axis xyz="0 -1 0" />
    <limit velocity="4.8" effort="1000" lower="-0.010" upper="0.019" />
    <dynamics damping="0.7" />
    <mimic joint="gripper_left_joint" multiplier="1" />
  </joint>

  <link
    name="gripper_right_link">
    <visual>
      <origin xyz="-0.062 0 0" rpy="0 0 0" />
      <geometry>
        <mesh filename="${meshes_file_direction}/gripper_right_palm.stl" scale="0.001 0.001 0.001" />
      </geometry>
      <material name="grey">
        <color rgba="0.2 0.2 0.2 1" />
      </material>
    </visual>

    <collision>
      <origin xyz="-0.062 0 0" rpy="0 0 0" />
      <geometry>
        <mesh filename="${meshes_file_direction}/gripper_right_palm.stl" scale="0.001 0.001 0.001" />
      </geometry>
    </collision>

    <inertial>
      <origin xyz="0 0 0" />
      <mass value="1.0e-03" />
      <inertia ixx="1.0e-06" ixy="0.0" ixz="0.0"
        iyy="1.0e-06" iyz="0.0"
        izz="1.0e-06" />
    </inertial>
  </link>

  <joint name="end_effector_joint" type="fixed">
    <parent link="flange" />
    <child link="end_effector_link" />
    <origin xyz="0.05 0.0 0.0" rpy="0 0 0" />
  </joint>

  <link name="end_effector_link">
  </link>

  <!-- <link name="ee_link" /> 
  <joint name="ee_fixed" type="fixed">
    <parent link="flange" />
    <child link="ee_link" />    
    <origin xyz="0 0 0.1" rpy="0 0 0" />
  </joint>  -->

  

</robot>