<?xml version="1.0" ?>
<!-- =================================================================================== -->
<!-- |    This document was autogenerated by xacro from smallrobot.urdf.xacro          | -->
<!-- |    EDITING THIS FILE BY HAND IS NOT RECOMMENDED                                 | -->
<!-- =================================================================================== -->
<!-- =================================================================================== -->
<!-- |    This document was autogenerated by xacro from
/home/roach/ros2_ws/src/smallrobot_description/urdf/smallrobot_description.xacro | -->
<!-- |    EDITING THIS FILE BY HAND IS NOT RECOMMENDED                                 | -->
<!-- =================================================================================== -->
<robot name="smallrobot">
  <gazebo>
    <plugin filename="libgazebo_ros2_control.so" name="gazebo_ros2_control">
      <robot_param>robot_description</robot_param>
      <robot_param_node>robot_state_publisher</robot_param_node>
      <!-- <parameters>/home/roach/ros2_ws/install/robotarm_controller/share/robotarm_controller/config/robotarm_controllers.yaml</parameters> -->
      <parameters>/home/roach/ros2_ws/install/robotarm_controller/share/robotarm_controller/config/robotarm_controllers.yaml</parameters>
    </plugin>
  </gazebo>
  <gazebo reference="base_link">
    <material>Gazebo/White</material>
  </gazebo>
  <gazebo reference="link1">
    <material>Gazebo/Orange</material>
  </gazebo>
  <gazebo reference="link2">
    <material>Gazebo/Orange</material>
  </gazebo>
  <gazebo reference="link3">
    <material>Gazebo/Orange</material>
  </gazebo>
  <gazebo reference="link4">
    <material>Gazebo/Orange</material>
  </gazebo>
  <gazebo reference="link5">
    <material>Gazebo/Orange</material>
  </gazebo>
  <gazebo reference="link6">
    <material>Gazebo/Orange</material>
  </gazebo>
  <!-- smallrobot_hw is the hw component name -->
  <ros2_control name="smallrobot_hw" type="system">
    <hardware>
      <plugin>gazebo_ros2_control/GazeboSystem</plugin>
    </hardware>
    <joint name="joint1">
      <command_interface name="position">
        <param name="min">-1.98</param>
        <param name="max">1.98</param>
      </command_interface>
      <state_interface name="position"/>
      <state_interface name="velocity"/>
    </joint>
    <joint name="joint2">
      <command_interface name="position">
        <param name="min">-1.41</param>
        <param name="max">1.34</param>
      </command_interface>
      <state_interface name="position"/>
      <state_interface name="velocity"/>
    </joint>
    <joint name="joint3">
      <command_interface name="position">
        <param name="min">-3.14159</param>
        <param name="max">1.22</param>
      </command_interface>
      <state_interface name="position"/>
      <state_interface name="velocity"/>
    </joint>
    <joint name="joint4">
      <command_interface name="position">
        <param name="min">-3.14159</param>
        <param name="max">3.14159</param>
      </command_interface>
      <state_interface name="position"/>
      <state_interface name="velocity"/>
    </joint>
    <joint name="joint5">
      <command_interface name="position">
        <param name="min">-2.42</param>
        <param name="max">2.42</param>
      </command_interface>
      <state_interface name="position"/>
      <state_interface name="velocity"/>
    </joint>
    <joint name="joint6">
      <command_interface name="position">
        <param name="min">-3.14159</param>
        <param name="max">3.14159</param>
      </command_interface>
      <state_interface name="position"/>
      <state_interface name="velocity"/>
    </joint>
    <joint name="joint7">
      <command_interface name="position">
        <param name="min">-1.570795</param>
        <param name="max">0.0</param>
      </command_interface>
      <state_interface name="position"/>
      <state_interface name="velocity"/>
    </joint>
    <joint name="joint8">
      <param name="mimic">joint7</param>
      <param name="multiplier">-1.0</param>
      <command_interface name="position">
        <param name="min">0.0</param>
        <param name="max">1.570795</param>
      </command_interface>
      <state_interface name="position"/>
      <state_interface name="velocity"/>
    </joint>
  </ros2_control>
  <link name="world"/>
  <!-- Fixed joint from world to base_link -->
  <joint name="world_to_base" type="fixed">
    <origin rpy="0 0 0" xyz="0 0 0"/>
    <parent link="world"/>
    <child link="base_link"/>
  </joint>
  <link name="base_link">
    <inertial>
      <mass value="1.0"/>
      <inertia ixx="1.0" ixy="0" ixz="0" iyy="1.0" iyz="0" izz="1.0"/>
      <!-- for cylinder robort formular in wiki <inertia ixx="${m*(3*r*r+h*h)/12}" ixy="0" ixz="0"
      iyy="${m*(3*r*r+h*h)/12}" iyz="0"
        izz="${m*r*r/2}" /> -->
    </inertial>
    <visual>
      <origin rpy="0 0 3.1415926" xyz="0.047 0.0121 0.25"/>
      <geometry>
        <mesh filename="package://smallrobot_description/meshes/link1.STL"/>
        <!-- <box size="0.5 0.5 0.5"/> -->
      </geometry>
      <material name="orange">
        <color rgba="1.0 0.5 0.0 0.8"/>
      </material>
    </visual>
    <collision>
      <origin rpy="0 0 3.1415926" xyz="0.047 0.0121 0.25"/>
      <geometry>
        <mesh filename="package://smallrobot_description/meshes/link1.STL"/>
      </geometry>
    </collision>
  </link>
  <joint name="joint1" type="revolute">
    <origin rpy="0 0 0" xyz="0 0 0.043"/>
    <axis xyz="0 0 1"/>
    <limit effort="100" lower="-2.0" upper="2.0" velocity="1.57"/>
    <parent link="base_link"/>
    <child link="link1"/>
  </joint>
  <link name="link1">
    <inertial>
      <mass value="0.5"/>
      <inertia ixx="1.0" ixy="0" ixz="0" iyy="1.0" iyz="0" izz="1.0"/>
      <!-- for cylinder robort formular in wiki <inertia ixx="${m*(3*r*r+h*h)/12}" ixy="0" ixz="0"
      iyy="${m*(3*r*r+h*h)/12}" iyz="0"
        izz="${m*r*r/2}" /> -->
    </inertial>
    <visual>
      <origin rpy="0 0 3.1415926" xyz="0.047 0.012 0.208"/>
      <geometry>
        <mesh filename="package://smallrobot_description/meshes/link2.STL"/>
      </geometry>
      <material name="orange">
        <color rgba="1.0 0.5 0.0 0.8"/>
      </material>
    </visual>
    <collision>
      <origin rpy="0 0 3.1415926" xyz="0.047 0.012 0.208"/>
      <geometry>
        <mesh filename="package://smallrobot_description/meshes/link2.STL"/>
      </geometry>
    </collision>
  </link>
  <joint name="joint2" type="revolute">
    <origin rpy="0 0 0" xyz="0.047 -0.0485 0.098"/>
    <axis xyz="0 1 0"/>
    <limit effort="100" lower="-1.5707963" upper="3.1415926" velocity="1.57"/>
    <parent link="link1"/>
    <child link="link2"/>
  </joint>
  <link name="link2">
    <inertial>
      <mass value="0.3"/>
      <inertia ixx="1.0" ixy="0" ixz="0" iyy="1.0" iyz="0" izz="1.0"/>
      <!-- for cylinder robort formular in wiki <inertia ixx="${m*(3*r*r+h*h)/12}" ixy="0" ixz="0"
      iyy="${m*(3*r*r+h*h)/12}" iyz="0"
        izz="${m*r*r/2}" /> -->
    </inertial>
    <visual>
      <origin rpy="1.5707963 0 3.1415926" xyz="0 0 0"/>
      <geometry>
        <mesh filename="package://smallrobot_description/meshes/link3.STL"/>
      </geometry>
      <material name="orange">
        <color rgba="1.0 0.5 0.0 0.8"/>
      </material>
    </visual>
    <collision>
      <origin rpy="1.5707963 0 3.1415926" xyz="0 0 0"/>
      <geometry>
        <mesh filename="package://smallrobot_description/meshes/link3.STL"/>
      </geometry>
    </collision>
  </link>
  <joint name="joint3" type="revolute">
    <origin rpy="0 0 0" xyz="0 0.08 0.111"/>
    <axis xyz="0 1 0"/>
    <limit effort="100" lower="-3.1415926" upper="1.5707963" velocity="1.57"/>
    <parent link="link2"/>
    <child link="link3"/>
  </joint>
  <link name="link3">
    <inertial>
      <mass value="0.1"/>
      <inertia ixx="1.0" ixy="0" ixz="0" iyy="1.0" iyz="0" izz="1.0"/>
      <!-- for cylinder robort formular in wiki <inertia ixx="${m*(3*r*r+h*h)/12}" ixy="0" ixz="0"
      iyy="${m*(3*r*r+h*h)/12}" iyz="0"
        izz="${m*r*r/2}" /> -->
    </inertial>
    <visual>
      <origin rpy="0 0 3.1415926" xyz="0.08 -0.0286 0.01"/>
      <geometry>
        <mesh filename="package://smallrobot_description/meshes/link4.STL"/>
      </geometry>
      <material name="orange">
        <color rgba="1.0 0.5 0.0 0.8"/>
      </material>
    </visual>
    <collision>
      <origin rpy="0 0 3.1415926" xyz="0.08 -0.0286 0.01"/>
      <geometry>
        <mesh filename="package://smallrobot_description/meshes/link4.STL"/>
      </geometry>
    </collision>
  </link>
  <joint name="joint4" type="revolute">
    <origin rpy="0 1.5707963 0" xyz="-0.026 -0.0316 0.0258"/>
    <axis xyz="0 0 1"/>
    <limit effort="100" lower="-1.5707963" upper="1.5707963" velocity="1.57"/>
    <parent link="link3"/>
    <child link="link4"/>
  </joint>
  <link name="link4">
    <inertial>
      <mass value="0.1"/>
      <inertia ixx="1.0" ixy="0" ixz="0" iyy="1.0" iyz="0" izz="1.0"/>
      <!-- for cylinder robort formular in wiki <inertia ixx="${m*(3*r*r+h*h)/12}" ixy="0" ixz="0"
      iyy="${m*(3*r*r+h*h)/12}" iyz="0"
        izz="${m*r*r/2}" /> -->
    </inertial>
    <visual>
      <origin rpy="0 1.5707963 1.5707963" xyz="0.016 0.003 0.106"/>
      <geometry>
        <mesh filename="package://smallrobot_description/meshes/link5.STL">
        </mesh>
      </geometry>
      <material name="orange">
        <color rgba="1.0 0.5 0.0 0.8"/>
      </material>
    </visual>
    <collision>
      <origin rpy="0 1.5707963 1.5707963" xyz="0.016 0.003 0.106"/>
      <geometry>
        <mesh filename="package://smallrobot_description/meshes/link5.STL"/>
      </geometry>
    </collision>
  </link>
  <joint name="joint5" type="revolute">
    <origin rpy="0 -1.5707963 0" xyz="0 0 0.144"/>
    <axis xyz="0 1 0"/>
    <limit effort="100" lower="-3.1415926" upper="3.1415926" velocity="1.57"/>
    <parent link="link4"/>
    <child link="link5"/>
  </joint>
  <link name="link5">
    <inertial>
      <mass value="0.02"/>
      <inertia ixx="1.0" ixy="0" ixz="0" iyy="1.0" iyz="0" izz="1.0"/>
      <!-- for cylinder robort formular in wiki <inertia ixx="${m*(3*r*r+h*h)/12}" ixy="0" ixz="0"
      iyy="${m*(3*r*r+h*h)/12}" iyz="0"
        izz="${m*r*r/2}" /> -->
    </inertial>
    <visual>
      <origin rpy="3.1415926 0 -1.5707963" xyz="0.018 0 0"/>
      <geometry>
        <mesh filename="package://smallrobot_description/meshes/link6.STL"/>
      </geometry>
      <material name="orange">
        <color rgba="1.0 0.5 0.0 0.8"/>
      </material>
    </visual>
    <collision>
      <origin rpy="3.1415926 0 -1.5707963" xyz="0.018 0 0"/>
      <geometry>
        <mesh filename="package://smallrobot_description/meshes/link6.STL"/>
      </geometry>
    </collision>
  </link>
  <joint name="joint6" type="revolute">
    <origin rpy="0 0 0" xyz="0.0253 0 0"/>
    <axis xyz="1 0 0"/>
    <limit effort="100" lower="-3.1415926" upper="3.1415926" velocity="1.57"/>
    <parent link="link5"/>
    <child link="link6"/>
  </joint>
  <link name="link6">
    <inertial>
      <mass value="0.01"/>
      <inertia ixx="1.0" ixy="0" ixz="0" iyy="1.0" iyz="0" izz="1.0"/>
      <!-- for cylinder robort formular in wiki <inertia ixx="${m*(3*r*r+h*h)/12}" ixy="0" ixz="0"
      iyy="${m*(3*r*r+h*h)/12}" iyz="0"
        izz="${m*r*r/2}" /> -->
    </inertial>
    <visual>
      <origin rpy="0 0 3.1415926" xyz="-0.0555 0.003 -0.016"/>
      <geometry>
        <mesh filename="package://smallrobot_description/meshes/link7.STL"/>
      </geometry>
      <material name="orange">
        <color rgba="1.0 0.5 0.0 0.8"/>
      </material>
    </visual>
    <collision>
      <origin rpy="0 0 3.1415926" xyz="-0.0555 0.003 -0.016"/>
      <geometry>
        <mesh filename="package://smallrobot_description/meshes/link7.STL"/>
      </geometry>
    </collision>
  </link>
  <link name="gripper_right">
    <visual>
      <origin rpy="0 0 -1.570795" xyz="-0.1 0.5 -0.1"/>
      <geometry>
        <mesh filename="package://smallrobot_description/meshes/gripper_right_palm.stl"/>
      </geometry>
    </visual>
  </link>
  <link name="gripper_left">
    <visual>
      <origin rpy="0 0 -1.570795" xyz="-0.04 0.5 -0.1"/>
      <geometry>
        <mesh filename="package://smallrobot_description/meshes/gripper_left_palm.stl"/>
        \
      
      </geometry>
    </visual>
  </link>
  <joint name="joint7" type="revolute">
    <origin rpy="0 0 0" xyz="-0.04 0.13 -0.1"/>
    <axis xyz="0 0 1"/>
    <limit effort="100" lower="-1.570795" upper="0.0" velocity="1.57"/>
    <parent link="link6"/>
    <child link="gripper_right"/>
  </joint>
  <joint name="joint8" type="revolute">
    <origin rpy="0 0 0" xyz="-0.22 0.13 -0.1"/>
    <axis xyz="0 0 1 "/>
    <limit effort="100" lower="0.0" upper="1.570795" velocity="1.57"/>
    <parent link="link6"/>
    <child link="gripper_left"/>
    <mimic joint="joint7" multiplier="-1"/>
  </joint>
  <!-- <link name="ee_link" />
  <joint name="ee_fixed" type="fixed">
    <parent link="link6" />
    <child link="ee_link" />
    <origin xyz="0 0 0.1" rpy="0 0 0" /> 
  </joint> -->
  <transmission name="transmission_1">
    <type>transmission_interface/SimpleTransmission</type>
    <actuator name="motor_1">
      <mechanicalReduction>4.8</mechanicalReduction>
    </actuator>
    <joint name="joint1">
      <hardwareInterface>hardware_interface/position</hardwareInterface>
      <!-- <hardwareInterface>hardware_interface/velocity</hardwareInterface>
        <hardwareInterface>hardware_interface/effort</hardwareInterface> -->
    </joint>
  </transmission>
  <transmission name="transmission_2">
    <type>transmission_interface/SimpleTransmission</type>
    <actuator name="motor_2">
      <mechanicalReduction>4.0</mechanicalReduction>
    </actuator>
    <joint name="joint2">
      <hardwareInterface>hardware_interface/position</hardwareInterface>
      <!-- <hardwareInterface>hardware_interface/velocity</hardwareInterface>
        <hardwareInterface>hardware_interface/effort</hardwareInterface> -->
    </joint>
  </transmission>
  <transmission name="transmission_3">
    <type>transmission_interface/SimpleTransmission</type>
    <actuator name="motor_3">
      <mechanicalReduction>5.0</mechanicalReduction>
    </actuator>
    <joint name="joint3">
      <hardwareInterface>hardware_interface/position</hardwareInterface>
      <!-- <hardwareInterface>hardware_interface/velocity</hardwareInterface>
        <hardwareInterface>hardware_interface/effort</hardwareInterface> -->
    </joint>
  </transmission>
  <transmission name="transmission_4">
    <type>transmission_interface/SimpleTransmission</type>
    <actuator name="motor_4">
      <mechanicalReduction>2.8</mechanicalReduction>
    </actuator>
    <joint name="joint4">
      <hardwareInterface>hardware_interface/position</hardwareInterface>
      <!-- <hardwareInterface>hardware_interface/velocity</hardwareInterface>
        <hardwareInterface>hardware_interface/effort</hardwareInterface> -->
    </joint>
  </transmission>
  <transmission name="transmission_5">
    <type>transmission_interface/SimpleTransmission</type>
    <actuator name="motor_5">
      <mechanicalReduction>2.1</mechanicalReduction>
    </actuator>
    <joint name="joint5">
      <hardwareInterface>hardware_interface/position</hardwareInterface>
      <!-- <hardwareInterface>hardware_interface/velocity</hardwareInterface>
        <hardwareInterface>hardware_interface/effort</hardwareInterface> -->
    </joint>
  </transmission>
  <transmission name="transmission_6">
    <type>transmission_interface/SimpleTransmission</type>
    <actuator name="motor_6">
      <mechanicalReduction>1.0</mechanicalReduction>
    </actuator>
    <joint name="joint6">
      <hardwareInterface>hardware_interface/position</hardwareInterface>
      <!-- <hardwareInterface>hardware_interface/velocity</hardwareInterface>
        <hardwareInterface>hardware_interface/effort</hardwareInterface> -->
    </joint>
  </transmission>
</robot>
